Workbook

Sheet Evaluation
A1: Crédit | C1: Critère | D1: Phases | E1: Prérequis | F1: Nb. crédits | G1: Scénario 1 | H1: Scénario 2 | I1: Scénario 3 | K1: Description v7 | L1: Description v6 | M1: Inséré dans PROG ENV | N1: Réponse du projet / observation
A2: Man 01 | B2: Planning du projet | C2: 1-3 | D2: ESQ | E2: - | F2: 1 | G2: 1 | H2: 1 | I2: 1 | J2: Mission de base ESSOR | K2: 1. Un programme de durabilité clair est développé avant l'achèvement de la conception initiale qui définit : 1.a. Les exigences du client, par exemple les conditions environnementales internes requises 1.b. Les objectifs et les cibles de durabilité comprenant le classement BREEAM visé, les objectifs de l'entreprise, etc. 1.c. Délais et budget 1.d. Liste des personnes consultées et les rendez-vous professionnels qui peuvent être requis, par exemple acousticien qualifié, etc. 1.e. Contraintes pour le projet, par exemple techniques, juridiques, physiques, environnementales. 2. Avant la finalisation de la conception préliminaire, l'équipe projet (client, équipe de conception et entrepreneur principal (voir M1 si non encore désigné)) se réunit afin de discuter, d'identifier et de définir les rôles, les responsabilités et les contributions pour chaque phase clé du projet. Lors de la définition des responsabilités, les points suivants doivent être pris en compte : 2.a. Besoins des utilisateurs du bâtiment. 2.b. Objectifs et stratégie de conception. 2.c. Exigences et contraintes particulières liées à l'installation et à la construction. 2.d. Évaluations des risques liés à la conception et à la construction, par exemple la réglementation nationale en matière de santé et de sécurité ou les meilleures pratiques, l'évaluation des risques de légionellose. 2.e. Exigences législatives, par exemple la réglementation locale en matière de construction, les exigences relatives au patrimoine. 2.f. Objectifs de développement durable du projet. 2.g. Mesures de protection écologique (le cas échéant). 2.h. Approvisionnement et chaîne logistique : approvisionnement responsable et éthique. 2.i. Identification et mesure de la réussite du projet conformément aux objectifs du cahier des charges. 2.j Budget et expertise technique du gestionnaire ou des occupants de l'immeuble en matière de maintenance des systèmes proposés. 2.k. Maintenabilité et adaptabilité des propositions. 2.l. Exigences relatives à la production de la documentation de projet et de la documentation destinée à l'utilisateur final. 2.m. Exigences relatives à la mise en service, à la formation et au support après-vente 3.L'équipe de projet démontre comment les contributions des parties prenantes à la réalisation du projet et leurs apports au processus de conception ont influencé les éléments suivants : 3.a. Cahier des charges initial 3.b. Plan d'exécution du projet 3.c. Stratégie de communication 3.d. Conception préliminaire 3.e. Conception finale (après construction) | L2: Un programme de durabilité clair est développé avant l'achèvement de la conception initiale qui définit : a. Les exigences du client, par exemple les conditions environnementales internes requises b. Les objectifs et les cibles de durabilité comprenant le classement BREEAM visé, les objectifs de l'entreprise, etc. c. Délais et budget d. Liste des personnes consultées et les rendez-vous professionnels qui peuvent être requis, par exemple acousticien qualifié, etc. e. Contraintes pour le projet, par exemple techniques, juridiques, physiques, environnementales.
A3: Man 01 | B3: Consultation des parties prenantes (tiers) | C3: 4-6 | D3: ESQ | E3: - | F3: 1 | G3: 0 | H3: 0 | I3: 0 | K3: 4. Avant l'achèvement de la phase de conception initiale, tous les tiers concernés ont été consultés par l'équipe de conception. 5. Le projet doit démontrer de manière concise comment les contributions des parties intéressées et les résultats de la consultation ont influencé ou modifié le cahier des charges initial et la conception préliminaire ; et comment ces modifications ont été intégrées à la conception finale après la construction. 6. Avant l’achèvement de la conception détaillée (conception technique ou équivalent), les commentaires recueillis lors de la consultation ont été transmis à toutes les parties concernées et reçus par elles. | L3: Avant l'achèvement de la phase de travail de conception initiale, tous les tiers concernés ont été consultés par l'équipe de conception.
A4: Man 01 | B4: Responsable durabilité (conception) | C4: 7-9 | D4: ESQ | E4: - | F4: 1 | G4: 1 | H4: 1 | I4: 1 | J4: Option AP | K4: 7. Un responsable durabilité a été désigné pour faciliter l'établissement et la réalisation d'objectifs de performance BREEAM pour le projet. Leur implication doit intervenir dès le début du processus de conception (voir M3.2) afin de : 7.a Collaborer avec l’équipe projet, y compris le client, pour examiner les liens entre les enjeux BREEAM et les aider à optimiser la performance globale du projet au regard de BREEAM, dès leur nomination et tout au long de la phase de conception préliminaire. 7.b Suivre l’avancement par rapport aux objectifs de performance convenus à toutes les étapes suivant leur nomination, lorsque leurs décisions ont un impact critique sur la performance BREEAM. 7.c Identifier de manière proactive les risques et les opportunités liés à l’atteinte des objectifs convenus. 7.d Fournir un retour d'information approprié à l'équipe projet afin de l'aider à prendre des mesures correctives et à atteindre ses objectifs de performance convenus. 7.e Suivre et, le cas échéant, coordonner la production des preuves appropriées par l'équipe projet. 8. Les objectifs de performance BREEAM définis ont été formellement convenus entre le client et l'équipe de conception ou projet au plus tard au stade de la conception préliminaire. 9. Pour obtenir ce crédit lors de l'évaluation intermédiaire de la conception, les objectifs de performance BREEAM convenus doivent être démontrés par la conception du projet. Ceci doit être démontré par le rapport d'évaluation de l'évaluateur BREEAM à l'étape de la conception. | L4: Un responsable durabilité a été désigné pour faciliter l'établissement et la réalisation d'objectifs de performance BREEAM pour le projet.
A5: Man 01 | B5: Responsable durabilité (suivi des progrès) | C5: 10-12 | D5: APS-APD-PRO-DCE | E5: - | F5: 1 | G5: 1 | H5: 1 | I5: 1 | J5: Option AP | K5: 10. Obtenir la certification BREEAM AP – Conception préliminaire (critères 7 à 9). 11. Un professionnel BREEAM Advisory Professional (AP) a été désigné pour suivre l'avancement du projet par rapport aux objectifs de performance BREEAM convenus tout au long du processus de conception et pour rendre compte formellement de cet avancement au client et à l'équipe de conception. Il doit : 11.a Collaborer avec l'équipe projet, y compris le client, afin d'examiner les liens entre les problématiques BREEAM et de les aider à optimiser la performance globale du projet par rapport à BREEAM tout au long de la phase de conception détaillée. 11.b Suivre l'avancement du projet par rapport aux objectifs de performance convenus au titre du critère 8 à toutes les étapes où les décisions ont un impact critique sur le cahier des charges, le processus d'appel d'offres et la performance BREEAM. 11.c Identifier de manière proactive les risques et les opportunités liés à l'atteinte des objectifs convenus au titre du critère 8. 11.d Fournir un retour d'information à l'équipe projet, le cas échéant, afin de l'aider à prendre des mesures correctives et à atteindre ses objectifs de performance convenus. 11.e Suivre et, le cas échéant, coordonner la production des éléments de preuve pertinents par l'équipe projet. 12 Le professionnel accrédité BREEAM AP – Conception doit participer aux réunions clés de l’équipe projet et de conception pendant les phases de conception préliminaire, de conception développée et de conception technique. Un rapport doit être établi pendant et avant la fin de chaque phase, au minimum. | L5: Un responsable durabilité est nommé pour suivre les progrès par rapport aux objectifs de performance BREEAM convenus tout au long du processus de conception et rendre compte formellement au client des progrès de l'équipe conception.
A6: Man 02 | B6: Analyse en coût global élémentaire | C6: 1-3 | D6: ESQ | E6: - | F6: 2 | G6: 0 | H6: 2 | I6: 1 | J6: Option étude en coût global | K6: 1. Une personne compétente réalise une évaluation préliminaire et une évaluation complète des options de coût du cycle de vie (CCV) des éléments de l'actif (au moins deux) au stade de la conception préliminaire, conformément à la norme ISO 15686-5:2017. 2. Le plan CCV des éléments : 2.a. Fournit une indication des coûts de remplacement futurs sur une période d’analyse définie par le client (par exemple, 20, 30, 50 ou 60 ans). 2.b. Comprend des estimations de la durée de vie, de la maintenance et des coûts d’exploitation. 3. Démontrer, à l'aide d'exemples appropriés fournis par l'équipe de conception, comment le plan LCC élémentaire a été utilisé pour influencer la conception et la spécification des bâtiments et des systèmes afin de minimiser les coûts du cycle de vie et de maximiser la valeur critique. | L6: Un coût de cycle de vie (LCC – Life Cycle Cost) élémentaire a été réalisé à l'étape de la conception initiale, ainsi que toute évaluation d'option de conception. Selon ISO 15686-5:2008
A7: Man 02 | B7: Plan de LCC au niveau composants | C7: 4-5 | D7: PRO-DCE | E7: - | F7: 1 | G7: 0 | H7: 1 | I7: 1 | J7: Option étude en coût global | K7: 4. Une personne compétente réalise une évaluation des options d'analyse du coût du cycle de vie (ACV) au niveau des composants (au moins deux) à la fin de la phase de conception technique (équivalente à la phase 4 du processus), conformément à la norme ISO 15686-5:2017. Cette évaluation inclut les types de composants suivants (le cas échéant) : 4.a Enveloppe (par exemple, bardage, fenêtres ou toiture). 4.b Services (par exemple, source de chaleur, source de refroidissement ou systèmes de contrôle, y compris les systèmes de contrôle d'éclairage intelligents par rapport aux systèmes de contrôle standard). 4.c Finitions (par exemple, murs, sols ou plafonds). 4.d Espaces extérieurs (par exemple, aménagements paysagers alternatifs, protection des limites de propriété). 5. Démontrer, à l'aide d'exemples appropriés fournis par l'équipe de conception, comment l'évaluation des options LCC au niveau des composants a été utilisée pour influencer la conception et la spécification des bâtiments et des systèmes afin de minimiser les coûts du cycle de vie et de maximiser la valeur critique. | L7: Un plan de LCC au niveau composants a été développé avant la fin du processus du PRO, selon la norme ISO 15686-5:2008
A8: Man 02 | B8: Suivi du coût du capital | C8: 6 | D8: AOR-DOE | E8: - | F8: 1 | G8: 1 | H8: 1 | I8: 1 | J8: Communication du montant au BRE (confidentiel) | K8: 6. Indiquez le coût d’investissement du bâtiment par unité de surface intérieure brute. | L8: Indiquer au BRE le coût total de l'opération
A9: Man 03 | B9: Prérequis | C9: 1-2 | D9: Chantier | E9: Pass, Good, Very Good | F9: 0 | G9: 0 | H9: 0 | I9: 0 | J9: A être mentionné sur tous les CCTP : provenance légal du bois (bois d'œuvre également, produits temporaire de chantier) | K9: 1. Tous les produits en bois et à base de bois utilisés dans le projet sont certifiés « Bois légalement récoltés et négocié » (FSC - PEFC) 2. L’ensemble de la législation et de la réglementation nationales en matière de santé et de sécurité sur les chantiers de construction sont prises en compte et mises en œuvre à toutes les phases du projet (voir CN1 page 58) : 2.a Conception de l’ouvrage : afin de minimiser les risques pour la santé et la sécurité. 2.b Planification et organisation des travaux préalables à la construction : afin de recueillir les informations relatives à la santé et à la sécurité auprès de toutes les parties prenantes concernées. 2.c Aménagement du chantier : afin de mettre en place les dispositifs de santé et de sécurité. 2.d Construction : afin de gérer, de contrôler et de rendre compte de la santé et de la sécurité du personnel du chantier. Ces informations doivent être synthétisées dans un rapport. | L9: Tous les produits en bois et à base de bois utilisés dans le projet sont certifiés « Bois légalement récoltés et négocié » (FSC - PEFC) Le projet se conforme aux obligations réglementaires de sécurité et de santé
A10: Man 03 | B10: Gestion environnementale | C10: 3-4 | D10: Chantier | E10: - | F10: 1 | G10: 0 | H10: 0 | I10: 1 | J10: Entreprises (qui construisent) sont ISO 14001 | K10: 3. Toutes les parties intervenant sur le chantier, à quelque étape que ce soit, doivent mettre en œuvre un système de management environnemental (SME) couvrant leurs principales activités. Ce SME doit être certifié par un organisme tiers selon la norme ISO 14001, EMAS (Système européen de management environnemental et d'audit) ou une norme équivalente. 4. Toutes les parties intervenant sur le chantier, à quelque étape que ce soit (par exemple, l'entrepreneur principal ou l'entreprise de démolition) doivent mettre en œuvre sur le site les meilleures pratiques en matière de prévention de la pollution, conformément aux politiques et procédures établies. Pour démontrer leur conformité, l'équipe projet doit compléter la liste de contrôle figurant dans le tableau 11, page 56, en indiquant comment l'objectif de chaque section (par exemple, la qualité de l'air) a été atteint, même par des moyens différents de ceux suggérés. Pour l'alignement avec la taxonomie européenne, veuillez vous référer à M5. | L10: L'entrepreneur principal est certifié ISO14001 ou équivalent. Mettre en place les meilleures pratiques en termes de politiques de prévention et procédures environnementales sur site.
A11: Man 03 | B11: Conseiller BRREAM (AP) | C11: 5-7 | D11: Chantier | E11: - | F11: 1 | G11: 1 | H11: 1 | I11: 1 | J11: Option AP | K11: 5. Le client doit convenir formellement avec l'entrepreneur des objectifs de performance relatifs à la certification BREEAM qui ont été fixés pour le projet. 6. Un accréditeur BREEAM (AP) doit être impliqué dans le projet au moment opportun et au niveau approprié afin de garantir l'atteinte des objectifs de performance convenus. Plus précisément, l'accréditeur doit : 6.a. Collaborer avec l'équipe projet, y compris le client, pour l'aider à optimiser la performance par rapport aux objectifs convenus tout au long de la construction, de la réception et de la clôture du projet. Cet accompagnement comprendra la prise en compte des liens entre les critères qui doivent être respectés dans tous les domaines du projet évalués par BREEAM (par exemple, Management, Énergie, Écologie, etc.), en allant au-delà des intentions de conception chaque fois que cela est possible. 6.b. Suivre l'avancement par rapport aux objectifs de performance convenus à toutes les étapes de la construction, en accordant une attention particulière aux décisions susceptibles d'avoir un impact critique sur la performance BREEAM, et en conservant tous les documents nécessaires à l'évaluation. 6.c. Identifier de manière proactive les risques et les opportunités liés aux processus d'approvisionnement et de construction, ainsi qu'à l'atteinte des objectifs convenus au titre du critère 5. 6.d Fournir un retour d'information rapide et régulier à l'entrepreneur et à l'équipe projet afin d'aider le projet à rester sur la bonne voie pour atteindre ses objectifs et de soutenir la mise en œuvre des actions correctives nécessaires. 6.e Le cas échéant, coordonner et aider l'équipe projet à fournir à l'évaluateur les éléments de preuve nécessaires à l'obtention des crédits. 7 Pour obtenir ce crédit lors de l'évaluation finale post-construction, le rapport de l'évaluateur soumis doit démontrer qu'un professionnel accrédité BREEAM a été désigné et que les objectifs de performance convenus ont été atteints de manière probante par le projet. | L11: Un responsable durabilité est nommé pour suivre le projet pour garantir la conformité continue avec les critères pertinents de performance et de processus de durabilité, et donc les objectifs BREEAM, au cours des étapes de construction, de livraison et de clôture.
A12: Man 03 | B12: Gestion responsable de la construction | C12: 8-9 | D12: Chantier | E12: Excellent (1 crédit), Outstanding (2 crédits) | F12: 2 | G12: 1 | H12: 1 | I12: 2 | J12: Mission de base ESSOR | K12: 8. Pour les projets de petite envergure ou les maisons individuelles : 8.a L’entrepreneur doit satisfaire aux exigences des points f, h, i, j et m (tels qu’ils figurent dans le tableau 10) pour obtenir un crédit. 8.b Si l’entrepreneur satisfait aux exigences des points cochés comme « requis pour un crédit (pour les projets standard) » dans le tableau 10, le projet de petite envergure ou la maison individuelle peut obtenir deux crédits. 9. Tous les bâtiments qui ne sont pas définis comme des projets à petite échelle ou des maisons individuelles sont considérés comme des projets standards et les crédits sont attribués comme suit : 9.a Tous les éléments cochés comme « requis pour un crédit (pour les projets standards) » dans le tableau 10 doivent être remplis pour qu’un crédit soit attribué. 9.b Les projets qui remplissent le critère 9.a ainsi que six autres éléments du tableau 10 peuvent se voir attribuer un deuxième crédit. | L12: le constructeur principal s’organise d’une manière qui garantisse un accès sûr et approprié au chantier, aux alentours et sur le chantier lui-même. Il respecte les critères identifiés par thème de la checklist (1point) et 6 critères de plus (2 points)
A13: Man 03 | B13: Prérequis - Suivi des impacts chantier | C13: 10 | D13: Chantier | E13: - | F13: 0 | G13: 0 | H13: 0 | I13: 0 | K13: 10. Attribuer la responsabilité de la surveillance du site à une personne nommée. Il s’agit d’une condition préalable à l’attribution de crédits pour la surveillance du site décrits ci-dessous. La personne responsable doit avoir l’autorité et l’expérience appropriées pour accéder aux données requises. Cela peut être le BREEAM AP, lorsqu'il a été nommé. Il sera tenu de surveiller, enregistrer et communiquer les données (lorsqu’elles sont mesurées) sur la consommation d’énergie, d’eau et de transport résultant de tous les processus de construction sur site (et de fabrication dédiée hors site) tout au long du programme de construction.
A14: Man 03 | B14: Suivi des impacts chantier - eau et énergie | C14: 11-16 | D14: Chantier | E14: - | F14: 1 | G14: 1 | H14: 1 | I14: 1 | J14: Mission de base ESSOR | K14: 11. Définir, dès la phase de conception, des objectifs de consommation énergétique du chantier en kWh (et, le cas échéant, en litres de carburant utilisés) résultant de l'utilisation des engins de chantier, des équipements (mobiles et fixes) et des installations de chantier. 12. Suivre et enregistrer les données relatives à la consommation énergétique décrite au critère 11 et démontrer que les objectifs de consommation ont été atteints. 13. Rendre compte des émissions totales de dioxyde de carbone (kgCO₂e) et de la consommation énergétique (électricité en kWh et litres de carburant) résultant du processus de construction. 14. Définir, dès la phase de conception, des objectifs de consommation d'eau potable (m³) liés à l'utilisation des engins de chantier, des équipements (mobiles et fixes) et des installations de chantier. 15. Suivre et enregistrer les données relatives à la consommation d'eau potable décrite au critère 14 et démontrer que les objectifs de consommation ont été atteints. 16. Utiliser les données collectées pour établir le calcul de la consommation nette totale d'eau résultant du processus de construction (m³), c'est-à-dire la consommation moins l'utilisation d'eau recyclée. | L14: Une personne sur site est en charge du suivi de la consommation d'énergie, des émissions de CO2 qui en résultent et de la consommation d'eau potable pour le chantier.
A15: Man 03 | B15: Suivi des impacts chantier - transport des matériaux de construction et des déchets | C15: 17-18 | D15: Chantier | E15: - | F15: 1 | G15: 1 | H15: 1 | I15: 1 | J15: Suivre les entrées de livraison | K15: 17. Définir des objectifs dès la phase de conception et surveiller et enregistrer les données relatives aux mouvements de transport et autres impacts résultant de la livraison de la majorité des matériaux de construction sur le chantier et de l'évacuation des déchets de construction (voir M4). Ce suivi doit au minimum couvrir : 17.a Le transport des matériaux du point d'approvisionnement au chantier, y compris le transport, le stockage intermédiaire et la distribution. 17.b Le périmètre de ce suivi doit couvrir au minimum les matériaux utilisés pour les éléments suivants : 17.b.i La superstructure, telle qu'indiquée dans le tableau 73 du document 03. 17.b.ii Les finitions intérieures, telles qu'indiquées dans le tableau 74 du document 03. 17.b.iii Les infrastructures et les aménagements extérieurs, tels qu'indiqués dans le tableau 75 du document 03. 17.b.iv Services essentiels du bâtiment, tels qu'ils figurent au tableau 76 du document 03. 17.c Transport des déchets de construction depuis le point de départ du chantier jusqu'au site de traitement ou au centre de valorisation. Le suivi doit couvrir les catégories de déchets de construction décrites dans le plan de gestion des déchets du projet. 18. À partir des données collectées, établir un rapport distinct pour les matériaux et les déchets, indiquant les émissions totales de dioxyde de carbone liées au transport (kgCO₂e), ainsi que la distance totale parcourue (km) et la quantité de carburant utilisée (litres). | L15: Suivre et enregistrer les données sur les mouvements de transport et les impacts résultant de la livraison de la majorité des matériaux des travaux de rénovation ou d'aménagement vers le chantier et des déchets.
A16: Man 03X | B16: Niveau exemplaire | C16: 19 | D16: Chantier | E16: - | F16: 1 | G16: 0 | H16: 0 | I16: 1 | K16: 19. Atteindre l'ensemble des items de la table 10. | L16: Atteindre l'ensemble des items de la table 10.
A17: Man 04 | B17: Calendrier et responsabilité | C17: 1-5 | D17: PRO-DCE-VISA-DET-AOR-DOE | E17: Very Good, Excellent, Outstanding | F17: 0 | G17: 0 | I17: 1 | J17: A faire en APD PRO | K17: 1. Élaborer un calendrier de mise en service et d'essais. Ce calendrier doit définir et inclure un échéancier approprié pour la mise en service et la remise en service de tous les systèmes techniques et de contrôle du bâtiment, complexes et non complexes, et pour les essais et l'inspection de l'enveloppe du bâtiment. 2. Le calendrier doit préciser les normes applicables auxquelles toutes les activités de mise en service seront conformes. Il s'agira notamment des codes de bonnes pratiques nationaux en matière de mise en service ou d'autres normes pertinentes, le cas échéant. Voir CN1. Tout équipement lié aux procédés ou à la fabrication, spécifié dans le cadre du projet, peut être exclu de l'évaluation, sauf s'il fait partie intégrante des services CVC du bâtiment, comme certains systèmes de récupération de chaleur. 3. Lorsqu'un système de gestion technique du bâtiment (GTB) est spécifié : 3.a. Procéder à la mise en service des systèmes d'air et d'eau une fois que tous les dispositifs de contrôle sont installés, câblés et fonctionnels. 3.b. Inclure les mesures physiques des températures ambiantes, des températures hors serpentin et autres paramètres clés, le cas échéant, dans les résultats de la mise en service. 3.c. L'installation GTB ou de contrôle doit fonctionner en mode automatique avec des conditions internes satisfaisantes avant la réception. 3.d. Tous les schémas et graphiques de la GTB (le cas échéant) sont entièrement installés et fonctionnels pour l'interface utilisateur avant la réception. 3.e. Former pleinement l'occupant ou l'équipe technique à l'utilisation du système. 4. Désigner un membre approprié de l'équipe projet pour surveiller et programmer la pré-mise en service, la mise en service et les essais. Le cas échéant, inclure les activités de remise en service pour le compte du client. 5. L’entrepreneur principal intègre le programme de mise en service et d’essais, les responsabilités et les critères dans son budget et le programme principal des travaux. Le programme doit prévoir le temps nécessaire à la réalisation de toutes les activités de mise en service. et d’essais avant la réception. | L17: Planifier le commissionnement, nommer un responsable au sein de l'équipe. Inclure le commissionnement au planning.
A18: Man 04 | B18: Commissionnement - mise en route | C18: 6-7 | D18: PRO-DCE-VISA-DET-AOR-DOE | E18: - | F18: 0 | G18: 0 | H18: 0 | I18: 1 | J18: Faire intervenir un spécialiste du commissionnement | K18: 6. Respecter le calendrier et les responsabilités (critères 1 à 5). 7. Pendant la phase de conception, le client ou l'entrepreneur principal désigne un membre approprié de l'équipe projet (voir critère 4), à condition qu'il ne participe pas aux travaux d'installation générale des systèmes techniques du bâtiment, avec les responsabilités suivantes : 7.a. Réaliser des revues de conception et fournir des conseils visant à optimiser le processus de mise en service. 7.b. Apporter son expertise en matière de gestion de la mise en service à la planification des travaux et pendant les phases d'installation. 7.c. Gérer la mise en service, les essais de performance et les phases de réception ou de post-réception. Pour les bâtiments dotés de systèmes et de services techniques complexes, ce rôle doit être assuré par un responsable de la mise en service spécialisé. | L18: Un spécialiste du commissionnement est désigné avant la fin de l'APD et est présent jusqu'à la livraison.
A19: Man 04 | B19: Essais et inspection de l'enveloppe | C19: 8-10 | D19: 4-5-6 | E19: - | F19: 1 | G19: 0 | H19: 0 | I19: 1 | J19: Faire intervenir un spécialiste de l'enveloppe | K19: 8. Respecter le calendrier et les responsabilités (critères 1 à 5). 9. Réaliser les essais et inspections post-construction afin de garantir l'intégrité de l'enveloppe du bâtiment, notamment la continuité de l'isolation, l'absence de ponts thermiques et de fuites d'air (par le biais de tests d'étanchéité à l'air et d'une inspection thermographique) (voir M1). Un professionnel qualifié effectue l'inspection et les essais conformément à la norme appropriée (voir M1.5). Pour la conformité à la taxonomie européenne, veuillez consulter M1.6. 10. Remédier à tout défaut identifié lors des essais et inspections post-construction avant la réception du bâtiment et la clôture du chantier. Tous les travaux de réparation doivent respecter les caractéristiques de performance requises pour le bâtiment ou l'élément, telles que définies lors de la conception (voir M1.4). | L19: l'intégrité des matériaux du bâtiment, y compris la continuité de l'isolation, l'évitement des ponts thermiques et les fuites d'air est assurée par la réalisation des essais et de l'inspection postconstruction. Les défaut identifiés sont corrigés avant la livraison du bâtiment
A20: Man 04 | B20: Livraison | C20: 11-12 | D20: AOR-DOE | E20: Very Good, Excellent, Outstanding | F20: 0 | G20: 0 | H20: 0 | I20: 1 | K20: 11. Avant la remise des clés, élaborer deux guides d'utilisation (voir M2) pour le bâtiment ou le logement, destinés aux utilisateurs suivants : 11.a Un guide d'utilisation non technique à distribuer aux occupants du bâtiment. 11.b Un guide d'utilisation technique destiné aux gestionnaires des installations (peut ne pas s'appliquer aux évaluations résidentielles sans parties partagées ou espaces communs gérés). Une version préliminaire est élaborée et discutée au préalable avec les utilisateurs (lorsque les occupants du bâtiment sont connus) afin de s'assurer que le guide est le plus approprié et utile possible. 12. Préparer deux programmes de formation (voir M3) adaptés aux dates de remise des clés et d'occupation prévues pour les utilisateurs suivants : 12.a Programme de formation non technique pour les occupants du bâtiment. 12.b Programme de formation technique pour les gestionnaires des installations. | L20: Un guide de l'utilisateur du bâtiment est rédigé avant la livraison pour distribution aux occupants du bâtiment et aux gestionnaires des locaux. Une formation est planifiée pour les occupants du bâtiment ou les gestionnaires des locaux.
A21: Man 05 | B21: Services de suivi après-vente | C21: 1-2 | D21: 6-7 | E21: - | F21: 0 | G21: 0 | H21: 0 | I21: 1 | K21: 1. Fournir un soutien après-vente aux occupants du bâtiment grâce à la mise en place d'une infrastructure et de ressources opérationnelles. Ceci comprend au minimum : 1.a Une réunion entre l'équipe ou la personne chargée du soutien après-vente et l'occupant ou l'équipe de gestion du bâtiment (avant l'emménagement initial, ou dès que possible par la suite) afin de : 1.a.i Présenter le soutien après-vente disponible, y compris le contenu du guide d'utilisation du bâtiment (le cas échéant) et le programme de formation. 1.a.ii Présenter les informations clés concernant les caractéristiques du bâtiment, notamment son objectif de conception et son utilisation, afin de garantir un fonctionnement aussi efficace et performant que possible. 1.b Formation à la gestion des installations sur site, comprenant : 1.b.i Visite guidée du bâtiment. 1.b.ii Présentation et familiarisation avec les systèmes du bâtiment, leurs commandes et leur utilisation conformément aux spécifications de conception et aux exigences opérationnelles. 1.c Assistance initiale pendant au moins le premier mois d'occupation du bâtiment, par exemple une présence hebdomadaire sur site, afin d'accompagner les utilisateurs et la direction du bâtiment (la fréquence dépendra de la complexité du bâtiment et de son exploitation). 1.d Assistance à plus long terme pour les occupants pendant au moins les 12 premiers mois suivant l'emménagement, par exemple une assistance téléphonique, une personne référente ou tout autre système approprié pour accompagner les utilisateurs et la direction du bâtiment. 2 Mise en place de l'infrastructure et des ressources opérationnelles nécessaires à la collecte et au suivi des données de consommation d'énergie et d'eau pendant au moins 12 mois après l'occupation significative du bâtiment. Cela facilite l’analyse des écarts entre les performances réelles et prévues, en vue d’ajuster les systèmes et les comportements des utilisateurs en conséquence (voir M1). | L21: Il y a (ou il y aura) une infrastructure de fonctionnement et des ressources en place pour fournir des services de suivi aux occupants du bâtiment ET pour coordonner la collecte et le suivi des données de consommation d'énergie et d'eau pour un minimum de 12 mois.
A22: Man 05 | B22: Commissionnement - première année | C22: 3 | D22: 6-7 | E22: Excellent, Outstanding | F22: 0 | G22: 0 | H22: 0 | I22: 1 | J22: Faire intervenir un spécialiste du commissionnement | K22: 3. Réaliser les activités de mise en service suivantes sur une période minimale de 12 mois, une fois le bâtiment occupé de manière significative : 3.a Systèmes complexes : Le responsable de la mise en service spécialisé devra : 3.a.i Identifier les modifications apportées par le propriétaire ou l’exploitant susceptibles d’avoir affecté ou amélioré les performances. 3.a.ii Tester tous les équipements techniques du bâtiment en conditions de charge maximale et partielle (voir CN1). 3.a.iii Le cas échéant, effectuer des tests pendant les périodes d’occupation extrême (forte ou faible). 3.a.iv Interroger les occupants du bâtiment (lorsqu’ils sont concernés par les équipements techniques complexes) afin d’identifier les problèmes ou les préoccupations concernant l’efficacité des systèmes. 3.a.v Comparer les performances énergétiques mesurées par sous-comptage aux performances énergétiques prévues. 3.a.vi Identifier les inefficacités et les points à améliorer. 3.a.vii Remettre en service les systèmes (après les travaux nécessaires pour répondre aux nouvelles charges) et intégrer les modifications apportées aux procédures d’exploitation dans les manuels d’exploitation et de maintenance. 3.b Systèmes simples : Le consultant externe, l’équipe de maintenance ou le gestionnaire des installations devra : 3.b.i Examiner le confort thermique, la ventilation et l’éclairage à trois, six et neuf mois après la mise en service, par des mesures ou grâce aux retours des occupants. 3.b.ii Identifier les défaillances et les points à améliorer. 3.b.iii Remettre en service les systèmes et intégrer les modifications pertinentes des procédures d’exploitation dans les manuels d’exploitation et de maintenance. | L22: Les activités de commissionnement saisonnier sont réalisées sur une période minimale de 12 mois, une fois que le bâtiment est occupé de manière importante.
A23: Man 05 | B23: Évaluation post-occupation | C23: 4-7 | D23: 7 | E23: - | F23: 0 | G23: 0 | H23: 0 | I23: 0 | J23: Coût d'une telle étude ? | K23: 4. Le client ou l'occupant du bâtiment s'engage à réaliser une évaluation post-occupation (EPO) un an après l'occupation substantielle du bâtiment. Cette évaluation permet de recueillir un retour d'information complet sur les performances en situation réelle (voir critère 5.b.v) et d'identifier les écarts entre les intentions de conception et les performances réelles. L'objectif est de mettre en évidence les améliorations ou interventions nécessaires et d'éclairer les processus opérationnels. 5. L'EPO est réalisée par un organisme indépendant et porte sur : 5.a. Un examen des intentions de conception et du processus de construction (examen des processus de conception, d'approvisionnement, de construction et de réception). 5.b. Un retour d'information d'un large éventail d'utilisateurs du bâtiment, y compris les gestionnaires d'installations, sur la conception et les conditions environnementales du bâtiment : 5.b.i Conditions environnementales intérieures (lumière, bruit, température, qualité de l'air). 5.b.ii Contrôle, exploitation et maintenance. 5.b.iii Installations et commodités. 5.b.iv Accès et agencement. 5.b.v Consommation d'énergie et d'eau (voir critère 2 et M1). 5.b.vi Autres points pertinents, le cas échéant. 6. L'organisme indépendant remet au client et aux occupants du bâtiment un rapport d'analyse des enseignements tirés. 7. Le client ou l'occupant du bâtiment s'engage à financer l'évaluation post-interventionnelle (EPI) à l'avance. Ceci implique la désignation d'un organisme indépendant pour réaliser l'EPI conformément au critère 5. | L23: Le client ou l'occupant du bâtiment prend l'engagement de procéder à un exercice d'évaluation post occupation (EPO) un an après l'occupation initiale du bâtiment.
A24: Man 05X | B24: Planning de transition zéro carbone | C24: 8 | D24: 7 | E24: - | F24: 0 | G24: 0 | H24: 0 | I24: 1 | J24: à chiffrer | K24: 8 Lorsque les objectifs de zéro émission nette de carbone ne sont pas atteints pour les performances opérationnelles et que des combustibles fossiles sont utilisés sur site, une personne compétente élabore un plan de transition zéro carbone démontrant comment l'actif atteindra la neutralité carbone en exploitation d'ici 2050 au plus tard (voir M2). | L24: Créer une feuille de route chiffrée (technique et financière) pour supprimer toute combustion fossile et atteindre le Net Zéro d'ici 2050 au plus tard (alignement sur l'engagement COP21), avec un suivi annuel des indicateurs.
A25: Hea 01 | B25: Prérequis | C25: 1 | E25: Outstanding | F25: 0 | G25: 0 | H25: 0 | I25: 0 | K25: 1. Atteindre l'une des options suivantes : 1a : Au moins 95 % des zones concernées doivent avoir des fenêtres (verticales ou inclinées) représentant au moins 20 % de la surface de la paroi environnante. 1b : Au moins 80 % des zones concernées doivent avoir une surface vitrée équivalente à au moins 7 % de la surface au sol. | L25: Option A : Au moins 95 % des zones concernées doivent avoir des fenêtres (verticales ou inclinées) représentant au moins 20 % de la surface de la paroi environnante. Option B : Au moins 80 % des zones concernées doivent avoir une surface vitrée équivalente à au moins 7 % de la surface au sol.
A26: Hea 01 | B26: Contrôle de l'éblouissement | C26: 2-4 | D26: PC-PRO-DCE | E26: - | F26: 0 | G26: 0 | H26: 0 | I26: 1 | J26: Peu de zones à risque, étude rapide ? Petite étude à faire | K26: 2. Identifier les zones à risque d'éblouissement à l'aide d'une évaluation des risques d'éblouissement. Cette évaluation justifie également les zones jugées non exposées à un risque d'éblouissement. 3. Lorsqu'un risque a été identifié dans une zone concernée du bâtiment, une stratégie de contrôle de l'éblouissement est mise en œuvre afin d'éliminer tout risque d'éblouissement (voir M2). 4. La stratégie de contrôle de l'éblouissement n'augmente pas la consommation d'énergie pour l'éclairage. Ceci est réalisé en : 4.a. Optimisant les niveaux de lumière naturelle par tous les temps (nuageux ou ensoleillé). 4.b. S'assurant que l'utilisation ou l'emplacement des protections solaires ne perturbe pas le fonctionnement des systèmes de contrôle de l'éclairage. | L26: Identifier les zones à risque via un diagnostic spécifique. Mettre en place des solutions pour éliminer l'éblouissement dans les zones à risque. Efficacité énergétique : La stratégie ne doit pas augmenter la consommation d'éclairage artificiel. Pour cela, il faut : Maximiser l'apport de lumière quel que soit le temps (nuageux ou ensoleillé). S'assurer que les protections solaires ne perturbent pas les systèmes de gestion automatique de l'éclairage.
A27: Hea 01 | B27: Eclairement naturel | C27: 5 | D27: ESQ-APS-APD | E27: - | F27: 1 | G27: 0 | H27: 1 | I27: 0 | J27: Etude ALJ à faire (points obtenus sur Fenouillet) | K27: 5. Les critères d’éclairage naturel ont été respectés selon l’une des options décrites dans le tableau 13, page 85 (voir M3.2) : 5.a Les zones concernées du bâtiment respectent les critères d’éclairement naturel moyen et minimal des bonnes pratiques, tels que décrits dans le tableau 13, page 85. OU 5.b Les zones concernées du bâtiment respectent tout niveau de recommandation selon les critères d’éclairement naturel de la norme EN 17037:2018+A1:2021. OU 5.c Les zones concernées du bâtiment atteignent au moins le niveau d’éclairement naturel « nominalement accepté » selon la norme IES LM-83-23. | L27: Montrer un niveau d'éclairement naturel suffisant (respect des seuils de luminance, ou d'autonomie en lumière du jour). Table 13 ou EN 17037:2018+A1:2021 ou ES LM-83-23
A28: Hea 01 | B28: Ensoleillement direct sur fenêtres (Résidentiel, santé, séjours longue durée) | C28: 6-7 | D28: ESQ-APS-APD | E28: - | F28: 0 | G28: 0 | H28: 0 | I28: 0 | J28: en résidentiel uniquement | K28: 6. Obtenir au moins un point pour « Éclairage naturel » (critère 5). 7. Toutes les unités concernées doivent comporter au moins une zone recevant au moins 3 heures d'ensoleillement direct par fenêtre le jour de l'équinoxe (21 mars ou 21 septembre, représentant les conditions annuelles moyennes), par ciel dégagé (voir M4). | L28: Toutes les unités concernées doivent posséder au moins une pièce recevant au moins 3 heures de soleil direct par les fenêtres le jour de l'équinoxe (21 mars ou 21 septembre).
A29: Hea 01 | B29: Vue sur l'extérieur | C29: 8-9 | D29: APS-APD-PRO-DCE | E29: - | F29: 1 | G29: 1 | H29: 1 | I29: 0 | J29: A vérifier sur plan mais obtenu sur Fenouillet | K29: 8. Option A (Distance à la fenêtre) : 95 % de la surface au sol dans 95 % des espaces doivent être à une distance d'une fenêtre permettant une vue adéquate. La taille de la fenêtre requise augmente avec la distance : < 8 m : Fenêtre ≥ 20 % de la paroi ; 8 à 11 m : Fenêtre ≥ 25 % de la paroi ; 11 à 14 m : Fenêtre ≥ 30 % de la paroi ; > 14 m : Fenêtre ≥ 35 % de la paroi. OU 9. Option B (Qualité visuelle) : 75 % de la surface au sol dans 95 % des espaces doivent offrir : Un angle de vue horizontal ≥ 28°. Une vue sur le "paysage" ainsi qu'au moins le ciel ou le sol. | L29: Option A (Distance à la fenêtre) : 95 % de la surface au sol dans 95 % des espaces doivent être à une distance d'une fenêtre permettant une vue adéquate. La taille de la fenêtre requise augmente avec la distance : < 8 m : Fenêtre ≥ 20 % de la paroi ; 8 à 11 m : Fenêtre ≥ 25 % de la paroi ; 11 à 14 m : Fenêtre ≥ 30 % de la paroi ; > 14 m : Fenêtre ≥ 35 % de la paroi. Option B (Qualité visuelle) : 75 % de la surface au sol dans 95 % des espaces doivent offrir : Un angle de vue horizontal ≥ 28°. Une vue sur le "paysage" ainsi qu'au moins le ciel ou le sol.
A30: Hea 01X | B30: Evaluation de l'éblouissement en lumière naturelle | C30: 10-11 | D30: APS-APD-PRO-DCE | E30: - | F30: 0 | G30: 0 | H30: 0 | I30: 1 | J30: Etude spécifique | K30: 10. Obtenir le crédit pour « Contrôle de l’éblouissement » (critères 2 à 4) 11. Une évaluation a été réalisée pour démontrer la conformité à l'une des exigences suivantes et à la méthode M6 : DGP (Probabilité d'Éblouissement) : Ne doit pas dépasser 0,40 pendant plus de 5 % des heures d'exploitation annuelles à tous les postes de travail. ASE (Exposition Solaire Annuelle) : Pas plus de 10 % de l'espace occupé ne doit recevoir un éclairement de 1 000 lux ou plus pendant plus de 250 heures par an. | L30: Validation du crédit sur le contrôle de l'éblouissement et restpect d'un des critères suivants : DGP (Probabilité d'Éblouissement) : Ne doit pas dépasser 0,40 pendant plus de 5 % des heures d'exploitation annuelles à tous les postes de travail. ASE (Exposition Solaire Annuelle) : Pas plus de 10 % de l'espace occupé ne doit recevoir un éclairement de 1 000 lux ou plus pendant plus de 250 heures par an.
A31: Hea 01X | B31: Eclairement naturel exemplaire | C31: 12 | D31: APS-APD-PRO-DCE | E31: - | F31: 1 | G31: 0 | H31: 0 | I31: 0 | J31: Non visé | K31: 12. Les critères d’éclairage naturel ont été respectés selon l’une des options suivantes : 12.a Les zones concernées du bâtiment satisfont aux critères exemplaires d’éclairement naturel ponctuel moyen et minimal, tels que définis dans le tableau 14, page 87. OU 12.b Les zones concernées du bâtiment satisfont à la note la plus élevée de la norme EN 17037:2018+A1:2021 OU de la norme IES LM-83-23 et aux critères pertinents du tableau 14, page 87. | L31: Atteinte du seuil exemplaire pour l'éclairement en lumière naturelle.
A32: Hea 02 | B32: Prérequis | C32: 1 | D32: APS-APD-PRO-DCE | E32: - | F32: 0 | G32: 0 | H32: 0 | I32: 0 | J32: Facile à respecter ? Oui marquage CE | K32: 1. Tout éclairage doit être conçu pour minimiser le papillotement (flicker) et les effets stroboscopiques (voir M1), y compris sur toute sa plage de gradation et de réglage des couleurs, le cas échéant. Ceci s'applique à tout éclairage intérieur et extérieur. EU Directive 2009/125/EC | L32: Toute l'installation d'éclairage doit être conçue pour minimiser le papillotement (flicker) et les effets stroboscopiques. EU Directive 2009/125/EC
A33: Hea 02 | B33: Qualité d'éclairage interne et externe | C33: 2-4 | D33: ESQ-VISA-DET | E33: - | F33: 1 | G33: 1 | H33: 1 | I33: 1 | J33: Conformité au normes en vigueur sur l'éclairage extérieur EN 13201 series (parts 1 to 5)(8), (9), (10), (11), (12) and EN 12464-2:2024 | K33: 2. L'éclairage intérieur de toutes les zones concernées du bâtiment est conçu pour être conforme à toutes les recommandations applicables de la norme EN 12464-1:2021(7) ou à une norme nationale alternative approuvée. L'éclairage intérieur doit être adapté aux tâches effectuées, en tenant compte de la concentration et du confort des utilisateurs. Ceci peut être démontré par une stratégie de conception d'éclairage fournissant des paramètres d'éclairage conformes aux guides de bonnes pratiques nationaux (voir CN2 page 99). Les critères de conformité doivent inclure, selon le cas : 2.a Niveaux et uniformité d'éclairement 2.b Limites d'éblouissement 2.c Apparence des couleurs (lorsqu'il existe des recommandations standard) 2.d Rendu des couleurs 3. Dans les zones où des écrans d'ordinateur sont régulièrement utilisés, il est impératif de confirmer que l'éclairage a été conçu pour limiter les risques d'éblouissement conformément à une limite d'éblouissement numérique spécifiée dans les guides de bonnes pratiques nationaux. Ces critères doivent inclure : 3.a Limites de luminance des luminaires pour éviter les reflets sur les écrans. Les données des fabricants de luminaires doivent être consultées pour confirmer ce point. 3.b Pour l'éclairage indirect, les recommandations se réfèrent à la luminance du plafond éclairé et non à celle du luminaire ; un calcul effectué par l'équipe de conception est généralement nécessaire pour le démontrer. 3.c Recommandations pour l'éclairage direct, l'éclairement du plafond et l'éclairement moyen des murs. 4. Tout l'éclairage extérieur situé dans la zone de construction est spécifié conformément à la série EN 13201 (parties 1 à 5) et à la norme EN 12464-2:2024. L'éclairage extérieur doit permettre aux utilisateurs d'effectuer des tâches visuelles en extérieur de manière efficace et précise, notamment la nuit. Ceci peut être démontré par une stratégie de conception d'éclairage fournissant des paramètres d'éclairage conformes aux guides nationaux de bonnes pratiques en matière d'éclairage (voir CN2 page 99). Les critères de conformité doivent inclure, le cas échéant pour chaque type d'application : 4.a Niveaux et uniformité de l'éclairement/luminance 4.b Limites d'éblouissement 4.c Rendu des couleurs | L33: L'éclairement, la température de couleur, l'IRC doivent être en conformité avec la norme (EN 12464-1).
A34: Hea 02 | B34: Zonage et commande de l'éclairage | C34: 5-8 | D34: APS-APD-PRO-DCE | E34: - | F34: 0 | G34: 0 | H34: 0 | I34: 1 | K34: 5. L'éclairage intérieur est zoné afin de permettre aux occupants de le contrôler conformément aux critères ci-dessous pour les zones concernées présentes dans le bâtiment, le cas échéant : 5.a Les postes de travail adjacents aux fenêtres ou aux atriums et les autres zones du bâtiment sont zonés et contrôlés séparément. 5.b Dans les bureaux où la disposition du mobilier est connue : zones de quatre postes de travail maximum. 5.c Salles de séminaire et de conférence : zonées pour les zones de présentation et le public. 5.d Espaces de bibliothèque : zonage séparé pour les rayonnages, les zones de lecture et les comptoirs. 5.e Espace d'enseignement ou de démonstration. 5.f Tableau blanc ou écran d'affichage. 5.g Auditoriums : zonage pour les zones de sièges, les zones de circulation et la zone du pupitre. 5.h Espaces restauration, restaurant, café : séparation des zones de service et des espaces de restauration 5.i Commerce de détail : séparation des zones d’exposition et des comptoirs 5.j Espaces bar : séparation des zones bar et des espaces de restauration 5.k Salles de jour, salles d’attente : séparation des zones de détente et d’activités, et des espaces de circulation avec commandes accessibles au personnel 5.l Chambres d’hôtel : séparation du couloir, de la salle de bain, du bureau et de l’espace nuit (le cas échéant). 6. Les zones utilisées pour l'enseignement, les séminaires ou les conférences sont dotées de commandes d'éclairage spécifiques, adaptées à la taille et à l'usage de l'espace. Cependant, un auditorium ou un amphithéâtre classique, avec des gradins et un pupitre/une zone de démonstration/de spectacle, est généralement équipé des commandes d'éclairage suivantes : 6.a Éclairage normal complet (pour permettre les entrées et sorties, le nettoyage, etc.) 6.b Éclairage de la zone de démonstration éteint et éclairage de la zone du public réduit (pour la projection de diapositives, tout en laissant suffisamment de lumière pour que le public puisse prendre des notes) 6.c Éclairage entièrement éteint (pour la projection de diapositives monochromes ou couleur, et pour les démonstrations visuelles ou les spectacles) 6.d Éclairage localisé séparé pour le pupitre. 7. Lorsque des commandes d'éclairage automatiques sont utilisées pour des raisons d'efficacité énergétique, une commande manuelle doit être prévue. 8. De plus, les critères relatifs au type de bâtiment figurant dans le tableau 15 ci-dessous (le cas échéant) | L34: Le zonage doit respecter 1 commande pour 4 personnes max en bureaux, le contrôle doit être laissé aux occupant
A35: Hea 02X | B35: Niveau exemplaire - contrôle de l'éclairage | C35: 9-10 | D35: PRO-DCE-AOR-DOE | E35: - | F35: 0 | G35: 0 | H35: 0 | I35: 0 | K35: 9. Dans chaque zone de contrôle d'un espace occupé, l'éclairage peut être atténué manuellement par les occupants jusqu'à 20 % maximum de son flux lumineux maximal, à l'aide d'interfaces de commande d'éclairage placées à des endroits accessibles. 10. Dans chaque zone de contrôle d'un espace occupé, la couleur de l'éclairage peut être ajustée sur une plage de température de couleur corrélée, de 2 700 K ou moins à 4 000 K ou plus. Des commandes automatiques limitent la température de couleur corrélée à 2 700 K ou moins l'après-midi et le soir. | L35: L'éclairage doit pouvoir être contrôlé graduellement jusqu'à moins de 20% de sa puissance maximale. La température de couleur doit pouvoir varier de 2 700k ou moins à 4 000 k ou plus.
A36: Hea 03 | B36: Effets non visuels de la lumière | C36: 1-4 | E36: - | F36: 0 | G36: 0 | H36: 0 | I36: 0 | J36: Pas de points sur l'éclairage naturel | K36: 1. Obtenir au moins un crédit pour « Éclairage naturel » dans Hea 01 Lumière naturelle. 2. Toutes les zones concernées doivent satisfaire à l'une des conditions suivantes, selon le cas : 2.a Lorsque les positions des occupants sont connues et fixes (voir M1.1) : Toutes les positions dans toutes les zones concernées du bâtiment reçoivent un éclairement vertical d'au moins 250 lux EDI mélanopiques au niveau des yeux des occupants pendant au moins quatre heures en journée (à partir de midi au plus tard). 2.b Lorsque les positions des occupants sont inconnues ou variables (voir M1.2) : L'éclairement cylindrique à hauteur des yeux dans chaque zone concernée du bâtiment correspond à au moins 250 lux EDI mélanopiques pendant au moins quatre heures en journée (à partir de midi au plus tard). 3. Des systèmes d'éclairage électrique et des commandes permettent d'ajuster le flux et le spectre de la lumière émise au fil du temps (réglage de la couleur) afin de réduire l'EDI mélanopique au niveau des yeux des occupants l'après-midi et le soir, selon le type d'application. 4. Dans les zones résidentielles d'un bâtiment, des systèmes et des commandes garantissent un EDI mélanopique inférieur ou égal à 10 lux pendant les trois heures précédant le coucher et inférieur ou égal à 1 lux pendant le sommeil, au niveau des yeux des occupants, dans toutes les zones concernées du bâtiment où une occupation résidentielle est prévue (voir Définitions). | L36: Avoir au moins 1 crédit pour la lumière naturelle. Toutes les zones concernées doivent respecter un niveau d'éclairement spécifique exprimé en lux mélanopique EDI (Equivalent Daylight Illuminance). Le seuil est de 250 lux mélanopique EDI pendant au moins 4 heures durant la journée (débutant au plus tard à midi). Modulation du Flux et du Spectre Le système d'éclairage électrique doit être capable d'ajuster son flux et sa sortie spectrale (Tunable White). Objectif : Permettre une réduction de l'EDI mélanopique l'après-midi et le soir afin de respecter les besoins physiologiques des occupants selon l'usage du bâtiment.
A37: Hea 04 | B37: Prérequis | C37: 1 | D37: APS-APD-PRO-DCE | E37: Pass | F37: 0 | G37: 0 | H37: 0 | I37: 0 | K37: 1. Les matériaux contenant de l'amiante ne doivent pas être prescrits ou installés. | L37: Les matériaux contenant de l'amiante ne doivent pas être prescrits ou installés.
A38: Hea 04 | B38: Plan de qualité de l'air intérieur (QAI) | C38: 2 | D38: APS-APD-PRO-DCE | E38: Very Good | F38: 0 | G38: 0 | H38: 0 | I38: 1 | J38: Plan QAI à vérifier | K38: 2. Un plan de qualité de l'air intérieur spécifique au site a été élaboré conformément à la note d'orientation 6 (GN06). Ce plan oriente la conception, les spécifications et l'installation afin d'optimiser l'amélioration de la qualité de l'air intérieur pendant l'occupation. Le plan doit prendre en compte les éléments suivants : 2.a Suppression des sources de contamination importantes 2.b Dilution et contrôle des autres sources de contamination, notamment : 2.b.i Exigences de qualité de l'air des zones spécialisées telles que les laboratoires, le cas échéant 2.c Procédures de purge et de renouvellement d'air avant occupation 2.d Tests et analyses effectués par un tiers 2.e Maintien de la qualité de l'air intérieur pendant l'utilisation 2.f Tout plan ou politique pertinent des autorités locales ou nationales (par exemple, zones de gestion de la qualité de l'air ou plans d'action locaux pour la qualité de l'air) | L38: Un plan de la qualité de l'air intérieur a été élaboré et mis en œuvre, avec l'objectif de faciliter un processus qui mène à concevoir, spécifier et implémenter des décisions d'installation et des actions qui minimisent la pollution de l'air intérieur.
A39: Hea 04 | B39: Ventilation | C39: 3-7 | D39: APS-APD-PRO-DCE | E39: Very Good (critère 7) | F39: 0 | G39: 0 | H39: 0 | I39: 1 | K39: Le bâtiment a été conçu pour minimiser la concentration et la recirculation des polluants à l'intérieur, comme suit : 3. Assurer l'apport d'air frais dans le bâtiment conformément à l'une des normes de bonnes pratiques en matière de ventilation énumérées ci-dessous (pour plus d'informations, voir M1.1) : 3.a ISO 17772-1:2017 Annexe I 3.b EN 16798-1:2019 Annexe B.3 3.c Norme nationale de bonnes pratiques en matière de ventilation. 4. Les voies de ventilation sont conçues pour minimiser la pénétration et l'accumulation de polluants atmosphériques à l'intérieur du bâtiment (voir M1.2). 5. Le cas échéant, les systèmes CVC doivent intégrer une filtration appropriée pour minimiser la pollution de l'air extérieur, telle que définie dans la norme EN 16798-1:2025, section B.4.2.(17). Les filtres spécifiés doivent atteindre une classification de l'air soufflé d'au moins SUP 2. Le niveau de filtration requis dépend de la qualité de l'air extérieur. 5.a Les immeubles résidentiels collectifs équipés de systèmes de climatisation centralisée peuvent démontrer leur conformité avec une classe de filtration F7 ou ePM1 50 %. 6 Les espaces occupés sont équipés de capteurs de dioxyde de carbone (CO₂) ou de capteurs de qualité de l'air étalonnés dans des zones spécifiques, conformément à la norme M1.3 et : 6.a Dans les bâtiments ou espaces ventilés mécaniquement : les capteurs sont reliés au système de ventilation mécanique et assurent une ventilation à la demande. 6.b Dans les bâtiments ou espaces ventilés naturellement : les capteurs peuvent alerter le propriétaire ou le gestionnaire du bâtiment lorsque les niveaux de CO₂ dépassent le seuil recommandé, ou sont reliés à des dispositifs de contrôle permettant d'ajuster la quantité d'air frais par exemple, des fenêtres à ouverture automatique ou des aérateurs de toiture. 6.c Le nombre total de capteurs et la surface intérieure nette des zones concernées couvertes par les capteurs sont déclarés via la plateforme BREEAM. 7 Dans les pays ou juridictions où fumer dans les bâtiments n’est pas interdit par la loi (voir Définitions), une interdiction de fumer couvrant toutes les zones publiques et réservées au personnel du bâtiment est mise en œuvre, et des panneaux « Interdit de fumer » sont placés dans des zones appropriées clairement visibles par tous les occupants (c.-à-d. les zones communes, les bureaux et les entrées du bâtiment). | L39: Les systèmes de ventilation minimisent la concentration de polluants dans le bâtiment, selon la norme EN ISO 17772-1 et EN 16798-1 sur les prises et rejets d'air, la filtration, et pour les espaces adéquat, un contrôle du CO2. Notamment 7 l/s/pers.
A40: Hea 04 | B40: Niveaux d'émission de composés organiques volatils (COV) (produits) | C40: 8-9 | D40: APS-APD-PRO-DCE | E40: - | F40: 0 | G40: 0 | H40: 0 | I40: 1 | K40: Pour un crédit : 8. Trois des cinq types de produits satisfont aux limites d'émission, aux exigences d'essai et à toutes les exigences supplémentaires énumérées dans le tableau 17 et le document M2. Lorsque les produits à base de bois ne font pas partie des trois types de produits sélectionnés, tous les produits à base de bois utilisés pour les aménagements et accessoires intérieurs doivent être testés et classés au minimum comme étant de classe E1 pour le formaldéhyde (voir CN2.2). Pour deux crédits : 9. Tous les types de produits satisfont aux limites d'émission, aux exigences d'essai et à toutes les exigences supplémentaires énumérées dans le tableau 17 et le document M2. | L40: 3 catégories sur 5 des éléments en contact avec l'air intérieur (peintures, vernis, produits en bois, revêtements de sol, faux plafonds, isolants thermiques et acoustiques, colles et joints) doivent respecter des seuils d'émission dans l'air intérieur pour les COVT ( ≤ 1.0 mg/m³), les formaldéhydes (≤ 0.06 mg/m³) et les produits cancérigènes 1A et 1B (≤ 0.001 mg/m³). (2 points si toutes les catégories valident le niveau)
...

Sheet Score
C1: Applicable | D1: Scénario 1 | E1: Scénario 2 | F1: Scénario 3 | G1: Applicable | H1: Scénario 1 | I1: Scénario 2 | J1: Scénario 3 | K1: % par crédit | L1: Scénario 1 | M1: Scénario 2 | N1: Scénario 3 | P1: Pondération BREEAM Project | Q1: Fully Fitted | R1: =SUM(R3:R12) -> 0.47196032 | S1: =SUM(S3:S12) -> 0.60985317 | T1: =SUM(T3:T12) -> 1.7495198 | U1: =SUM(U3:U12) -> 1.085 | Z1: Non residential weighting France
A2: Management | B2: Man 01 | C2: =SUMIFS(Evaluation!$F$2:$F$142,Evaluation!$A$2:$A$142,$B2&"*",Evaluation!$A$2:$A$142,"<>*X*") -> 4 | D2: =SUMIFS(Evaluation!$G$2:$G$142,Evaluation!$A$2:$A$142,$B2&"*",Evaluation!$A$2:$A$142,"<>*X*") -> 3 | E2: =SUMIFS(Evaluation!$H$2:$H$142,Evaluation!$A$2:$A$142,$B2&"*",Evaluation!$A$2:$A$142,"<>*X*") -> 3 | F2: =SUMIFS(Evaluation!$I$2:$I$142,Evaluation!$A$2:$A$142,$B2&"*",Evaluation!$A$2:$A$142,"<>*X*") -> 3 | G2: =SUM(C2:C6) -> 15 | H2: =SUM(D2:D6) -> 8 | I2: =SUM(E2:E6) -> 11 | J2: =SUM(F2:F6) -> 18 | K2: =Q3/G2 -> 0.0073333333 | L2: =H2*K2 -> 0.058666667 | M2: =I2*K2 -> 0.080666667 | N2: =J2*K2 -> 0.132 | P2: Thème | Q2: Pondération | R2: Scénario 1 | S2: Scénario 2 | T2: Scénario 3 | U2: Maximum | V2: Scénario 1 | W2: Scénario 2 | X2: Scénario 3 | Z2: Fully Fitted | AA2: Shell only | AB2: Shell and core
B3: Man 02 | C3: =SUMIFS(Evaluation!$F$2:$F$142,Evaluation!$A$2:$A$142,$B3&"*",Evaluation!$A$2:$A$142,"<>*X*") -> 4 | D3: =SUMIFS(Evaluation!$G$2:$G$142,Evaluation!$A$2:$A$142,$B3&"*",Evaluation!$A$2:$A$142,"<>*X*") -> 1 | E3: =SUMIFS(Evaluation!$H$2:$H$142,Evaluation!$A$2:$A$142,$B3&"*",Evaluation!$A$2:$A$142,"<>*X*") -> 4 | F3: =SUMIFS(Evaluation!$I$2:$I$142,Evaluation!$A$2:$A$142,$B3&"*",Evaluation!$A$2:$A$142,"<>*X*") -> 3 | P3: =$A$2 -> Management | Q3: =IF($Q$1=$Z$2,Z3,IF($Q$1=$AA$2,AA3,AB3)) -> 0.11 | R3: =L2 -> 0.058666667 | S3: =M2 -> 0.080666667 | T3: =N2 -> 0.132 | U3: =Q3 -> 0.11 | V3: =R3/$U3 -> 0.53333333 | W3: =S3/$U3 -> 0.73333333 | X3: =T3/$U3 -> 1.2 | Z3: 0.11 | AA3: 0.1243 | AB3: 0.1048
B4: Man 03 | C4: =SUMIFS(Evaluation!$F$2:$F$142,Evaluation!$A$2:$A$142,$B4&"*",Evaluation!$A$2:$A$142,"<>*X*") -> 6 | D4: =SUMIFS(Evaluation!$G$2:$G$142,Evaluation!$A$2:$A$142,$B4&"*",Evaluation!$A$2:$A$142,"<>*X*") -> 4 | E4: =SUMIFS(Evaluation!$H$2:$H$142,Evaluation!$A$2:$A$142,$B4&"*",Evaluation!$A$2:$A$142,"<>*X*") -> 4 | F4: =SUMIFS(Evaluation!$I$2:$I$142,Evaluation!$A$2:$A$142,$B4&"*",Evaluation!$A$2:$A$142,"<>*X*") -> 6 | P4: =$A$7 -> Health and Wellbeing | Q4: =IF($Q$1=$Z$2,Z4,IF($Q$1=$AA$2,AA4,AB4)) -> 0.19 | R4: =L7 -> 0.078333333 | S4: =M7 -> 0.11 | T4: =N7 -> 0.52166667 | U4: =Q4 -> 0.19 | V4: =R4/$U4 -> 0.4122807 | W4: =S4/$U4 -> 0.57894737 | X4: =T4/$U4 -> 2.745614 | Z4: 0.19 | AA4: 0.1093 | AB4: 0.1248
